{
  "application_id": "APP_20250920_163048",
  "business_name": "My Test upload",
  "status": "failed",
  "error": "LLM not available - using fallback",
  "traceback": "Traceback (most recent call last):\n  File \"c:\\work\\boarding\\merchant-onboarding-ai-project\\ui\\app.py\", line 341, in run_workflow\n    result = loop.run_until_complete(run_with_streaming())\n  File \"C:\\Python313\\Lib\\asyncio\\base_events.py\", line 720, in run_until_complete\n    return future.result()\n           ~~~~~~~~~~~~~^^\n  File \"c:\\work\\boarding\\merchant-onboarding-ai-project\\ui\\app.py\", line 323, in run_with_streaming\n    async for event in workflow.astream(initial_state):\n    ...<11 lines>...\n                    save_agent_result(app_id, current_results)\n  File \"C:\\Users\\Test\\AppData\\Roaming\\Python\\Python313\\site-packages\\langgraph\\pregel\\main.py\", line 2937, in astream\n    async for _ in runner.atick(\n    ...<13 lines>...\n            yield o\n  File \"C:\\Users\\Test\\AppData\\Roaming\\Python\\Python313\\site-packages\\langgraph\\pregel\\_runner.py\", line 295, in atick\n    await arun_with_retry(\n    ...<15 lines>...\n    )\n  File \"C:\\Users\\Test\\AppData\\Roaming\\Python\\Python313\\site-packages\\langgraph\\pregel\\_retry.py\", line 137, in arun_with_retry\n    return await task.proc.ainvoke(task.input, config)\n           ^^^^^^^^^^^^^^^^^^^^^^^^^^^^^^^^^^^^^^^^^^^\n  File \"C:\\Users\\Test\\AppData\\Roaming\\Python\\Python313\\site-packages\\langgraph\\_internal\\_runnable.py\", line 695, in ainvoke\n    input = await asyncio.create_task(\n            ^^^^^^^^^^^^^^^^^^^^^^^^^^\n        step.ainvoke(input, config, **kwargs), context=context\n        ^^^^^^^^^^^^^^^^^^^^^^^^^^^^^^^^^^^^^^^^^^^^^^^^^^^^^^\n    )\n    ^\n  File \"C:\\Users\\Test\\AppData\\Roaming\\Python\\Python313\\site-packages\\langgraph\\_internal\\_runnable.py\", line 463, in ainvoke\n    ret = await self.afunc(*args, **kwargs)\n          ^^^^^^^^^^^^^^^^^^^^^^^^^^^^^^^^^\n  File \"c:\\work\\boarding\\merchant-onboarding-ai-project\\ui\\..\\src\\..\\agents\\data-validation\\src\\agent.py\", line 34, in data_validation_agent\n    llm = get_llm()\n  File \"c:\\work\\boarding\\merchant-onboarding-ai-project\\ui\\..\\src\\..\\agents\\data-validation\\src\\agent.py\", line 19, in get_llm\n    raise Exception(\"LLM not available - using fallback\")\nException: LLM not available - using fallback\nDuring task with name 'data_validation' and id '932dc7ab-94aa-67f8-2663-5b57734d2a0d'\n",
  "failed_at": "2025-09-20T16:31:13.079713"
}